Traceback (most recent call last):
  File "C:\Users\Ashwi\Code\repository\job-board-flask\dev\lib\site-packages\sqlalchemy\engine\base.py", line 3280, in _wrap_pool_connect
    return fn()
  File "C:\Users\Ashwi\Code\repository\job-board-flask\dev\lib\site-packages\sqlalchemy\pool\base.py", line 310, in connect
    return _ConnectionFairy._checkout(self)
  File "C:\Users\Ashwi\Code\repository\job-board-flask\dev\lib\site-packages\sqlalchemy\pool\base.py", line 868, in _checkout
    fairy = _ConnectionRecord.checkout(pool)
  File "C:\Users\Ashwi\Code\repository\job-board-flask\dev\lib\site-packages\sqlalchemy\pool\base.py", line 476, in checkout
    rec = pool._do_get()
  File "C:\Users\Ashwi\Code\repository\job-board-flask\dev\lib\site-packages\sqlalchemy\pool\impl.py", line 145, in _do_get
    with util.safe_reraise():
  File "C:\Users\Ashwi\Code\repository\job-board-flask\dev\lib\site-packages\sqlalchemy\util\langhelpers.py", line 70, in __exit__
    compat.raise_(
  File "C:\Users\Ashwi\Code\repository\job-board-flask\dev\lib\site-packages\sqlalchemy\util\compat.py", line 208, in raise_
    raise exception
  File "C:\Users\Ashwi\Code\repository\job-board-flask\dev\lib\site-packages\sqlalchemy\pool\impl.py", line 143, in _do_get
    return self._create_connection()
  File "C:\Users\Ashwi\Code\repository\job-board-flask\dev\lib\site-packages\sqlalchemy\pool\base.py", line 256, in _create_connection
    return _ConnectionRecord(self)
  File "C:\Users\Ashwi\Code\repository\job-board-flask\dev\lib\site-packages\sqlalchemy\pool\base.py", line 371, in __init__
    self.__connect()
  File "C:\Users\Ashwi\Code\repository\job-board-flask\dev\lib\site-packages\sqlalchemy\pool\base.py", line 665, in __connect
    with util.safe_reraise():
  File "C:\Users\Ashwi\Code\repository\job-board-flask\dev\lib\site-packages\sqlalchemy\util\langhelpers.py", line 70, in __exit__
    compat.raise_(
  File "C:\Users\Ashwi\Code\repository\job-board-flask\dev\lib\site-packages\sqlalchemy\util\compat.py", line 208, in raise_
    raise exception
  File "C:\Users\Ashwi\Code\repository\job-board-flask\dev\lib\site-packages\sqlalchemy\pool\base.py", line 661, in __connect
    self.dbapi_connection = connection = pool._invoke_creator(self)
  File "C:\Users\Ashwi\Code\repository\job-board-flask\dev\lib\site-packages\sqlalchemy\engine\create.py", line 590, in connect
    return dialect.connect(*cargs, **cparams)
  File "C:\Users\Ashwi\Code\repository\job-board-flask\dev\lib\site-packages\sqlalchemy\engine\default.py", line 597, in connect
    return self.dbapi.connect(*cargs, **cparams)
  File "C:\Users\Ashwi\Code\repository\job-board-flask\dev\lib\site-packages\psycopg2\__init__.py", line 122, in connect
    conn = _connect(dsn, connection_factory=connection_factory, **kwasync)
psycopg2.OperationalError: connection to server at "localhost" (::1), port 5050 failed: Connection refused (0x0000274D/10061)
	Is the server running on that host and accepting TCP/IP connections?
connection to server at "localhost" (127.0.0.1), port 5050 failed: Connection refused (0x0000274D/10061)
	Is the server running on that host and accepting TCP/IP connections?


The above exception was the direct cause of the following exception:

Traceback (most recent call last):
  File "C:\Users\Ashwi\Code\repository\job-board-flask\models.py", line 33, in create_all
    db.create_all()
  File "C:\Users\Ashwi\Code\repository\job-board-flask\dev\lib\site-packages\flask_sqlalchemy\__init__.py", line 1094, in create_all
    self._execute_for_all_tables(app, bind, 'create_all')
  File "C:\Users\Ashwi\Code\repository\job-board-flask\dev\lib\site-packages\flask_sqlalchemy\__init__.py", line 1086, in _execute_for_all_tables
    op(bind=self.get_engine(app, bind), **extra)
  File "C:\Users\Ashwi\Code\repository\job-board-flask\dev\lib\site-packages\sqlalchemy\sql\schema.py", line 4888, in create_all
    bind._run_ddl_visitor(
  File "C:\Users\Ashwi\Code\repository\job-board-flask\dev\lib\site-packages\sqlalchemy\engine\base.py", line 3146, in _run_ddl_visitor
    with self.begin() as conn:
  File "C:\Users\Ashwi\Code\repository\job-board-flask\dev\lib\site-packages\sqlalchemy\engine\base.py", line 3062, in begin
    conn = self.connect(close_with_result=close_with_result)
  File "C:\Users\Ashwi\Code\repository\job-board-flask\dev\lib\site-packages\sqlalchemy\engine\base.py", line 3234, in connect
    return self._connection_cls(self, close_with_result=close_with_result)
  File "C:\Users\Ashwi\Code\repository\job-board-flask\dev\lib\site-packages\sqlalchemy\engine\base.py", line 96, in __init__
    else engine.raw_connection()
  File "C:\Users\Ashwi\Code\repository\job-board-flask\dev\lib\site-packages\sqlalchemy\engine\base.py", line 3313, in raw_connection
    return self._wrap_pool_connect(self.pool.connect, _connection)
  File "C:\Users\Ashwi\Code\repository\job-board-flask\dev\lib\site-packages\sqlalchemy\engine\base.py", line 3283, in _wrap_pool_connect
    Connection._handle_dbapi_exception_noconnection(
  File "C:\Users\Ashwi\Code\repository\job-board-flask\dev\lib\site-packages\sqlalchemy\engine\base.py", line 2117, in _handle_dbapi_exception_noconnection
    util.raise_(
  File "C:\Users\Ashwi\Code\repository\job-board-flask\dev\lib\site-packages\sqlalchemy\util\compat.py", line 208, in raise_
    raise exception
  File "C:\Users\Ashwi\Code\repository\job-board-flask\dev\lib\site-packages\sqlalchemy\engine\base.py", line 3280, in _wrap_pool_connect
    return fn()
  File "C:\Users\Ashwi\Code\repository\job-board-flask\dev\lib\site-packages\sqlalchemy\pool\base.py", line 310, in connect
    return _ConnectionFairy._checkout(self)
  File "C:\Users\Ashwi\Code\repository\job-board-flask\dev\lib\site-packages\sqlalchemy\pool\base.py", line 868, in _checkout
    fairy = _ConnectionRecord.checkout(pool)
  File "C:\Users\Ashwi\Code\repository\job-board-flask\dev\lib\site-packages\sqlalchemy\pool\base.py", line 476, in checkout
    rec = pool._do_get()
  File "C:\Users\Ashwi\Code\repository\job-board-flask\dev\lib\site-packages\sqlalchemy\pool\impl.py", line 145, in _do_get
    with util.safe_reraise():
  File "C:\Users\Ashwi\Code\repository\job-board-flask\dev\lib\site-packages\sqlalchemy\util\langhelpers.py", line 70, in __exit__
    compat.raise_(
  File "C:\Users\Ashwi\Code\repository\job-board-flask\dev\lib\site-packages\sqlalchemy\util\compat.py", line 208, in raise_
    raise exception
  File "C:\Users\Ashwi\Code\repository\job-board-flask\dev\lib\site-packages\sqlalchemy\pool\impl.py", line 143, in _do_get
    return self._create_connection()
  File "C:\Users\Ashwi\Code\repository\job-board-flask\dev\lib\site-packages\sqlalchemy\pool\base.py", line 256, in _create_connection
    return _ConnectionRecord(self)
  File "C:\Users\Ashwi\Code\repository\job-board-flask\dev\lib\site-packages\sqlalchemy\pool\base.py", line 371, in __init__
    self.__connect()
  File "C:\Users\Ashwi\Code\repository\job-board-flask\dev\lib\site-packages\sqlalchemy\pool\base.py", line 665, in __connect
    with util.safe_reraise():
  File "C:\Users\Ashwi\Code\repository\job-board-flask\dev\lib\site-packages\sqlalchemy\util\langhelpers.py", line 70, in __exit__
    compat.raise_(
  File "C:\Users\Ashwi\Code\repository\job-board-flask\dev\lib\site-packages\sqlalchemy\util\compat.py", line 208, in raise_
    raise exception
  File "C:\Users\Ashwi\Code\repository\job-board-flask\dev\lib\site-packages\sqlalchemy\pool\base.py", line 661, in __connect
    self.dbapi_connection = connection = pool._invoke_creator(self)
  File "C:\Users\Ashwi\Code\repository\job-board-flask\dev\lib\site-packages\sqlalchemy\engine\create.py", line 590, in connect
    return dialect.connect(*cargs, **cparams)
  File "C:\Users\Ashwi\Code\repository\job-board-flask\dev\lib\site-packages\sqlalchemy\engine\default.py", line 597, in connect
    return self.dbapi.connect(*cargs, **cparams)
  File "C:\Users\Ashwi\Code\repository\job-board-flask\dev\lib\site-packages\psycopg2\__init__.py", line 122, in connect
    conn = _connect(dsn, connection_factory=connection_factory, **kwasync)
sqlalchemy.exc.OperationalError: (psycopg2.OperationalError) connection to server at "localhost" (::1), port 5050 failed: Connection refused (0x0000274D/10061)
	Is the server running on that host and accepting TCP/IP connections?
connection to server at "localhost" (127.0.0.1), port 5050 failed: Connection refused (0x0000274D/10061)
	Is the server running on that host and accepting TCP/IP connections?

(Background on this error at: https://sqlalche.me/e/14/e3q8)
Traceback (most recent call last):
  File "C:\Users\Ashwi\Code\repository\job-board-flask\dev\lib\site-packages\sqlalchemy\engine\base.py", line 3280, in _wrap_pool_connect
    return fn()
  File "C:\Users\Ashwi\Code\repository\job-board-flask\dev\lib\site-packages\sqlalchemy\pool\base.py", line 310, in connect
    return _ConnectionFairy._checkout(self)
  File "C:\Users\Ashwi\Code\repository\job-board-flask\dev\lib\site-packages\sqlalchemy\pool\base.py", line 868, in _checkout
    fairy = _ConnectionRecord.checkout(pool)
  File "C:\Users\Ashwi\Code\repository\job-board-flask\dev\lib\site-packages\sqlalchemy\pool\base.py", line 476, in checkout
    rec = pool._do_get()
  File "C:\Users\Ashwi\Code\repository\job-board-flask\dev\lib\site-packages\sqlalchemy\pool\impl.py", line 145, in _do_get
    with util.safe_reraise():
  File "C:\Users\Ashwi\Code\repository\job-board-flask\dev\lib\site-packages\sqlalchemy\util\langhelpers.py", line 70, in __exit__
    compat.raise_(
  File "C:\Users\Ashwi\Code\repository\job-board-flask\dev\lib\site-packages\sqlalchemy\util\compat.py", line 208, in raise_
    raise exception
  File "C:\Users\Ashwi\Code\repository\job-board-flask\dev\lib\site-packages\sqlalchemy\pool\impl.py", line 143, in _do_get
    return self._create_connection()
  File "C:\Users\Ashwi\Code\repository\job-board-flask\dev\lib\site-packages\sqlalchemy\pool\base.py", line 256, in _create_connection
    return _ConnectionRecord(self)
  File "C:\Users\Ashwi\Code\repository\job-board-flask\dev\lib\site-packages\sqlalchemy\pool\base.py", line 371, in __init__
    self.__connect()
  File "C:\Users\Ashwi\Code\repository\job-board-flask\dev\lib\site-packages\sqlalchemy\pool\base.py", line 665, in __connect
    with util.safe_reraise():
  File "C:\Users\Ashwi\Code\repository\job-board-flask\dev\lib\site-packages\sqlalchemy\util\langhelpers.py", line 70, in __exit__
    compat.raise_(
  File "C:\Users\Ashwi\Code\repository\job-board-flask\dev\lib\site-packages\sqlalchemy\util\compat.py", line 208, in raise_
    raise exception
  File "C:\Users\Ashwi\Code\repository\job-board-flask\dev\lib\site-packages\sqlalchemy\pool\base.py", line 661, in __connect
    self.dbapi_connection = connection = pool._invoke_creator(self)
  File "C:\Users\Ashwi\Code\repository\job-board-flask\dev\lib\site-packages\sqlalchemy\engine\create.py", line 590, in connect
    return dialect.connect(*cargs, **cparams)
  File "C:\Users\Ashwi\Code\repository\job-board-flask\dev\lib\site-packages\sqlalchemy\engine\default.py", line 597, in connect
    return self.dbapi.connect(*cargs, **cparams)
  File "C:\Users\Ashwi\Code\repository\job-board-flask\dev\lib\site-packages\psycopg2\__init__.py", line 122, in connect
    conn = _connect(dsn, connection_factory=connection_factory, **kwasync)
psycopg2.OperationalError: connection to server at "localhost" (::1), port 5432 failed: FATAL:  password authentication failed for user "postgres"


The above exception was the direct cause of the following exception:

Traceback (most recent call last):
  File "C:\Users\Ashwi\Code\repository\job-board-flask\models.py", line 33, in create_all
    db.create_all()
  File "C:\Users\Ashwi\Code\repository\job-board-flask\dev\lib\site-packages\flask_sqlalchemy\__init__.py", line 1094, in create_all
    self._execute_for_all_tables(app, bind, 'create_all')
  File "C:\Users\Ashwi\Code\repository\job-board-flask\dev\lib\site-packages\flask_sqlalchemy\__init__.py", line 1086, in _execute_for_all_tables
    op(bind=self.get_engine(app, bind), **extra)
  File "C:\Users\Ashwi\Code\repository\job-board-flask\dev\lib\site-packages\sqlalchemy\sql\schema.py", line 4888, in create_all
    bind._run_ddl_visitor(
  File "C:\Users\Ashwi\Code\repository\job-board-flask\dev\lib\site-packages\sqlalchemy\engine\base.py", line 3146, in _run_ddl_visitor
    with self.begin() as conn:
  File "C:\Users\Ashwi\Code\repository\job-board-flask\dev\lib\site-packages\sqlalchemy\engine\base.py", line 3062, in begin
    conn = self.connect(close_with_result=close_with_result)
  File "C:\Users\Ashwi\Code\repository\job-board-flask\dev\lib\site-packages\sqlalchemy\engine\base.py", line 3234, in connect
    return self._connection_cls(self, close_with_result=close_with_result)
  File "C:\Users\Ashwi\Code\repository\job-board-flask\dev\lib\site-packages\sqlalchemy\engine\base.py", line 96, in __init__
    else engine.raw_connection()
  File "C:\Users\Ashwi\Code\repository\job-board-flask\dev\lib\site-packages\sqlalchemy\engine\base.py", line 3313, in raw_connection
    return self._wrap_pool_connect(self.pool.connect, _connection)
  File "C:\Users\Ashwi\Code\repository\job-board-flask\dev\lib\site-packages\sqlalchemy\engine\base.py", line 3283, in _wrap_pool_connect
    Connection._handle_dbapi_exception_noconnection(
  File "C:\Users\Ashwi\Code\repository\job-board-flask\dev\lib\site-packages\sqlalchemy\engine\base.py", line 2117, in _handle_dbapi_exception_noconnection
    util.raise_(
  File "C:\Users\Ashwi\Code\repository\job-board-flask\dev\lib\site-packages\sqlalchemy\util\compat.py", line 208, in raise_
    raise exception
  File "C:\Users\Ashwi\Code\repository\job-board-flask\dev\lib\site-packages\sqlalchemy\engine\base.py", line 3280, in _wrap_pool_connect
    return fn()
  File "C:\Users\Ashwi\Code\repository\job-board-flask\dev\lib\site-packages\sqlalchemy\pool\base.py", line 310, in connect
    return _ConnectionFairy._checkout(self)
  File "C:\Users\Ashwi\Code\repository\job-board-flask\dev\lib\site-packages\sqlalchemy\pool\base.py", line 868, in _checkout
    fairy = _ConnectionRecord.checkout(pool)
  File "C:\Users\Ashwi\Code\repository\job-board-flask\dev\lib\site-packages\sqlalchemy\pool\base.py", line 476, in checkout
    rec = pool._do_get()
  File "C:\Users\Ashwi\Code\repository\job-board-flask\dev\lib\site-packages\sqlalchemy\pool\impl.py", line 145, in _do_get
    with util.safe_reraise():
  File "C:\Users\Ashwi\Code\repository\job-board-flask\dev\lib\site-packages\sqlalchemy\util\langhelpers.py", line 70, in __exit__
    compat.raise_(
  File "C:\Users\Ashwi\Code\repository\job-board-flask\dev\lib\site-packages\sqlalchemy\util\compat.py", line 208, in raise_
    raise exception
  File "C:\Users\Ashwi\Code\repository\job-board-flask\dev\lib\site-packages\sqlalchemy\pool\impl.py", line 143, in _do_get
    return self._create_connection()
  File "C:\Users\Ashwi\Code\repository\job-board-flask\dev\lib\site-packages\sqlalchemy\pool\base.py", line 256, in _create_connection
    return _ConnectionRecord(self)
  File "C:\Users\Ashwi\Code\repository\job-board-flask\dev\lib\site-packages\sqlalchemy\pool\base.py", line 371, in __init__
    self.__connect()
  File "C:\Users\Ashwi\Code\repository\job-board-flask\dev\lib\site-packages\sqlalchemy\pool\base.py", line 665, in __connect
    with util.safe_reraise():
  File "C:\Users\Ashwi\Code\repository\job-board-flask\dev\lib\site-packages\sqlalchemy\util\langhelpers.py", line 70, in __exit__
    compat.raise_(
  File "C:\Users\Ashwi\Code\repository\job-board-flask\dev\lib\site-packages\sqlalchemy\util\compat.py", line 208, in raise_
    raise exception
  File "C:\Users\Ashwi\Code\repository\job-board-flask\dev\lib\site-packages\sqlalchemy\pool\base.py", line 661, in __connect
    self.dbapi_connection = connection = pool._invoke_creator(self)
  File "C:\Users\Ashwi\Code\repository\job-board-flask\dev\lib\site-packages\sqlalchemy\engine\create.py", line 590, in connect
    return dialect.connect(*cargs, **cparams)
  File "C:\Users\Ashwi\Code\repository\job-board-flask\dev\lib\site-packages\sqlalchemy\engine\default.py", line 597, in connect
    return self.dbapi.connect(*cargs, **cparams)
  File "C:\Users\Ashwi\Code\repository\job-board-flask\dev\lib\site-packages\psycopg2\__init__.py", line 122, in connect
    conn = _connect(dsn, connection_factory=connection_factory, **kwasync)
sqlalchemy.exc.OperationalError: (psycopg2.OperationalError) connection to server at "localhost" (::1), port 5432 failed: FATAL:  password authentication failed for user "postgres"

(Background on this error at: https://sqlalche.me/e/14/e3q8)
